<?xml version="1.0"?>
<!-- 

  ROS urdf definition of TEO torso using xacro

  RoboticsLab, University Carlos III of Madrid

  Joint names and properties are according to REP-120:
  Coordinate Frames for Humanoids Robots

  http://ros.org/reps/rep-0120.html

-->

<robot name="teo" xmlns:xacro="http://ros.org/wiki/xacro">

<!-- *** TEO HEAD PARAMETERS -->
  <xacro:property name="prop_kg_motor_vol_unit" value="6229.073482" /> <!-- Relation Kg - Volume Unit -->


<!-- Link lengths -->
	<xacro:property name="head_link1" value="0.13" />
	<!--xacro:property name="waist_link2" value="0.287" /-->
	<xacro:property name="head_link2" value="0.100" /> 
        <!-- head_link2 is an approximate value, right now this value is not relevant /-->

<!-- Minimum angles -->
	<xacro:property name="head_yaw_lower" value="${-29 * deg_to_rad}" />
  <xacro:property name="head_pitch_lower" value="${-73 * deg_to_rad}" />

<!-- Maximum angles -->
	<xacro:property name="head_yaw_upper" value="${8.4 * deg_to_rad}" />
	<xacro:property name="head_pitch_upper" value="${73.0 * deg_to_rad}" />

<!-- Effort limit of the angles -->
	<xacro:property name="head_yaw_effort" value="30.0" />
	<xacro:property name="head_pitch_effort" value="30.0" />


<!-- Velocity limit of the angles-->
	<xacro:property name="head_yaw_velocity" value="3.0" />
	<xacro:property name="head_pitch_velocity" value="3.0" />

<!-- Damping of the joints-->
	<xacro:property name="head_yaw_damping" value="0.0" />
	<xacro:property name="head_pitch_damping" value="0.0" />

<!-- Friction of the joints--> <!-- IT'S NOT USED IN GAZEBO-->
	<xacro:property name="head_yaw_friction" value="0.0" />
	<xacro:property name="head_pitch_friction" value="0.0" />

<!-- Joint reductions-->
	<xacro:property name="head_yaw_reduction" value="1.0" />
	<xacro:property name="head_pitch_reduction" value="1.0" />


<!-- *** HEAD TREE -->

  <!-- Links -->
  <link name="head_yaw_link" >
    <inertial>
      <origin xyz="0.0 0.0 -0.045" rpy="0 0 0"/>
      <mass value="1.0"/>
      <inertia
        ixx="0.028026e-2" ixy="-0.0" ixz="-0.0"
        iyy="0.028026e-2" iyz="0.0"
        izz="0.015756e-2" />
    </inertial>
    <xacro:insert_visualization_head_yaw/>
  </link>

  <link name="head_pitch_link" >
    <inertial>
      <origin xyz="-0.004280 0.0 0.105394" rpy="0 0 0"/>
      <mass value="1.0"/>
    <inertia
        ixx="1.469540" ixy="-0.000003" ixz="-0.012716"
        iyy="1.610027" iyz="0.000005" 
        izz="2.205351" />
    </inertial>
    <xacro:insert_visualization_head_pitch/>
  </link>


  <!-- Joints -->
  <joint name="head_yaw" type="revolute">
    <parent link="waist_pitch_link"/>
    <child link="head_yaw_link"/>
    <origin xyz="0 0 ${chest_link}" rpy="0 0 0" />
    <axis xyz="0 0 1"/>
    <limit velocity="${head_yaw_velocity}" effort="${head_yaw_effort}" lower="${head_yaw_lower}" upper="${head_yaw_upper}"/>
  </joint>

  <joint name="head_pitch" type="revolute">
    <parent link="head_yaw_link"/>
    <child link="head_pitch_link"/>
    <origin xyz="0 0 ${head_link1}" rpy="0 0 0" />
    <axis xyz="0 1 0"/>
    <limit velocity="${head_pitch_velocity}" effort="${head_pitch_effort}" lower="${head_pitch_lower}" upper="${head_pitch_upper}"/>
  </joint>

  <xacro:waist_joint_simple_transmission axis="yaw" reduction="${head_yaw_reduction}"/>
  <xacro:waist_joint_simple_transmission axis="pitch" reduction="${head_pitch_reduction}"/>
</robot>
